

# 异常

Golang中没有结构化的异常，使用`panic`抛出错误，`recover`捕获错误，也没有`try catch`的概念，Go的创始人们认为前者会消耗更多资源，而且会破坏正常的代码结构。

所以，Go语言的思想主张中：

- 如果一个函数可能出现异常，应该将异常作为返回值返回，没有就返回`nil`
- 每次调用可能出现异常的函数时，都应该主动进行检查并做出对应的处理，处理语句被称为 **卫述语句**

Go创始人们希望以此将异常掌握在程序员的手上，保证每次操作产生的影响达到最小。以上概念对于已经习惯了`try catch`的程序员（笔者也是）来说是难以理解的，Go的异常算是一大特色，同时也是一个经常**被人诟病**的点。



## `panic`

`panic()`是一个内置函数，如果函数中书写了`panic`语句，会终止其后要执行的代码，然后按照`defer`的逆序执行，直到`goroutine`整个退出，并报告错误。



## `recover`

`recover()`是一个内置函数，用于控制一个`goroutine`的`panicking`行为，捕获`panic`，从而影响程序。在`defer`函数中，通过一个`recover`来终止一个`goroutine`的`panicking`过程，从而恢复代码的正常运行，同时也可以获取到由`panic`传递的`error`。

<br/>

::: warning 注意

1. 利用`recover`处理异常时，`defer`必须在`panic`之前定义，另外`recover`只有在`defer`调用的函数中才有效，否则无法捕获`panic`

2. `recover`处理异常后，逻辑并不会恢复到`panic`发生的那个地方去，而是跑到`defer`之后的那个点

:::



**简单示例**

```go
func main() {
	defer func() {
		if err := recover(); err != nil {
			fmt.Println("recover", err.(string))
		}
	}()

	panic("panic exception!")
}
```

输出

```go
recover panic exception!
```

这是一段很简单的程序，`panic`抛出，`defer`调用`recover`捕获并输出错误信息



**复杂示例**

```go
func main() {
	fmt.Println("main start")
	//头部defer调用
	defer func() {
		if err := recover(); err != nil {
			fmt.Println("recover1", err.(string))
		}
	}()

	//匿名函数调用
	func() {
		//匿名函数defer
		defer func() {
			if err := recover(); err != nil {
				fmt.Println("recover2", err.(string))
			}
		}()

		panic("panic exception2!")
	}()

	panic("panic exception1!")

	fmt.Println("main end")
}
```

接下来可以分析一下究竟会输出什么：

1. `main`函数被执行，压入运行时栈中
2. `main`函数开头的输出`main start`
3. 接下来匿名`defer`被压入”栈1“中
4. 执行匿名函数`func(){}()`，匿名函数被压入运行时栈中
5. 匿名函数中`defer`被压入”栈2“中
6. 抛出`panic()`
7. 匿名函数中的`defer`被调用，捕获`panic`，并输出`recover2 panic exception2!`
8. 匿名函数调用结束，匿名函数出运行时栈
9. 抛出`panic()`
10. `main`函数中的`defer`被调用，不会`panic`，并输出`recover1 panic exception1!`
11. `main`函数出运行时栈
12. 程序结束

所以输出结果为：

```go
main start
recover2 panic exception2!
recover1 panic exception1!
```

由于`recover`语句捕获异常后，并不会回到抛出异常的语句后，而是会回到`defer`后，而`defer`的执行时间是在函数结束之前，所以最后一行代码

永远不会被执行到。`defer`调用其实是没有栈这个结构的，只是这样更加方便理解，具体的原理的话可以在**刨根问底**此板块了解。



`recover()`只有只有在延迟调用内直接调用才会终止错误，否则总是返回`nil`，未捕获的错误都会沿调用堆栈向外传递。

```go
func main() {
	defer func() { //有效
		fmt.Println(1, recover())
	}()

	defer recover() //无效

	defer fmt.Println(3, recover()) //无效

	defer func() { //无效
		func() {
			fmt.Println(4, recover())
		}()
	}()

	panic("panic exception!")
}
```



## 代码保护

如果希望执行`panic`后的代码片段的话，可以将`panic`片段重构为匿名函数调用。

```go
func main() {
	fmt.Println("start")
    
	func() {//需要保护的代码
		defer func() {
			if err := recover(); err != nil {
				fmt.Println(err.(string))
			}
		}()
		panic("exception")//会抛出panic的代码
	}()
	fmt.Println("end")
}
```

从这一段代码可以开始感觉到异常处理部分为什么被诟病了

输出

```go
start
exception
end 
```

上面一段代码非常难看，试想一下如果每一次异常都要这么写的话岂不是会非常繁琐，所以我们来简单优化一下

首先封装一个`Try`函数，它的两个参数都是函数，`apply`函数是可能会发生`panic`的代码段，`handler`函数则是用于异常处理的函数

```go
func TryPanic(apply func(), handler func(e interface{})) {
	defer func() {
		if err := recover(); err != nil {
			handler(err)
		}
	}()
	apply()
}
```

使用

```go
func main() {
	fmt.Println("start")

	TryPanic(func() {
		fmt.Println("保护代码执行中")
		panic("发生异常了!")
	}, func(e interface{}) {
		fmt.Println(e)
		fmt.Println("异常已被捕获,后续代码正常执行")
	})

	fmt.Println("end")
}
```

输出

```go
start
保护代码执行中
发生异常了!
异常已被捕获,后续代码正常执行
end
```

这样使用起来会优雅很多



## Error

除了使用`panic`之外，还可以使函数返回一个`error`接口对象

可以使用`errors.New`或者`fmt.Errorf`创建错误对象

首先创建一个`TryError`函数

```go
func TryError(apply func() error, handler func(e interface{})) {
	if err := apply(); err != nil {
		handler(err)
	}
}
```

然后使用

```go
func main() {
	fmt.Println("start")
	TryError(func() error {
		fmt.Println("保护代码执行中")
		return errors.New("发生异常")
	}, func(e interface{}) {
		fmt.Println(e)
		fmt.Println("异常已被处理，后续程序正常运行")
	})
	fmt.Println("end")
}
```

输出结果

```
start
保护代码执行中                
发生异常                      
异常已被处理，后续程序正常运行
end  
```



## `panic`和`error`的区别

事实上，Go语言中的`error`更接近其他语言中的`Exception`，因为`error`是认为可控制的，而`panic`是不太可控的

`panic`通常用于代表非常严重的错误，严重到足以打断程序的正常运行

而`error`通常用于表示没那么严重的错误



**作为模块提供者**

**按照规范，作为模块提供者，对外的接口应该准确的返回 error，而不应该出现自定义的 panic**。因为对于使用者来说他没有义务来捕捉你模块内部的问题，也不应该关心这个问题。否则又退化为了`try catch` 形式。但是当真正的 panic 出现时，绝对不要无脑的catch 住，返回一个 error，让上层函数明确的接收到，避免出现更大的问题。

**作为业务编写者**

作为业务代码，我觉得很重要的一点是可维护性。**如果违反这个 error 的规范能够极大提示可读性，节约大量的工作量，那么应该果断的使用 panic 来做流程控制**。而且在语言使用过程中违背设计者的本意是一个很常见的事情，新语言被创造的背后也是为了解决问题，更好的提升大家的开发效率。所以即使和设计者的本意冲突又何妨呢？当然了，期待未来出现一个合适的流程控制语法，可以更好的满足大家的需求。
